=> wandb run name : resnet18_leuven_bce resnet18_leuven_bce
=> torch version : 1.10.1+cu111
=> ngpus : 2
=> modeling the network resnet18 ...
=> num of params: 53107337 (202M)
=> building the oprimizer ...
=> building the dataloader ...
=> building the criterion ...
=> starting training engine ...
> /home/siddsuresh97/Projects/cs839-autoencoder/models/resnet.py(97)forward()
     96         import ipdb;ipdb.set_trace()
---> 97         x = self.encoder(x)
     98         return x
> /home/siddsuresh97/Projects/cs839-autoencoder/models/resnet.py(97)forward()
     96         import ipdb;ipdb.set_trace()
---> 97         x = self.encoder(x)
     98         return x
torch.Size([128, 2048, 7, 7])
Traceback (most recent call last):
  File "/home/siddsuresh97/Projects/cs839-autoencoder/train.py", line 251, in <module>
    main(args)
  File "/home/siddsuresh97/Projects/cs839-autoencoder/train.py", line 99, in main
    main_worker(ngpus_per_node, args)
  File "/home/siddsuresh97/Projects/cs839-autoencoder/train.py", line 173, in main_worker
    do_train(train_loader, model, criterion, optimizer, epoch, args, leuven_bce_transposed)
  File "/home/siddsuresh97/Projects/cs839-autoencoder/train.py", line 218, in do_train
    output, leuven_output = model(input)
  File "/home/siddsuresh97/packages/anaconda3/lib/python3.9/site-packages/torch/nn/modules/module.py", line 1102, in _call_impl
    return forward_call(*input, **kwargs)
  File "/home/siddsuresh97/packages/anaconda3/lib/python3.9/site-packages/torch/nn/parallel/data_parallel.py", line 168, in forward
    outputs = self.parallel_apply(replicas, inputs, kwargs)
  File "/home/siddsuresh97/packages/anaconda3/lib/python3.9/site-packages/torch/nn/parallel/data_parallel.py", line 178, in parallel_apply
    return parallel_apply(replicas, inputs, kwargs, self.device_ids[:len(replicas)])
  File "/home/siddsuresh97/packages/anaconda3/lib/python3.9/site-packages/torch/nn/parallel/parallel_apply.py", line 86, in parallel_apply
    output.reraise()
  File "/home/siddsuresh97/packages/anaconda3/lib/python3.9/site-packages/torch/_utils.py", line 434, in reraise
    raise exception
RuntimeError: Caught RuntimeError in replica 0 on device 0.
Original Traceback (most recent call last):
  File "/home/siddsuresh97/packages/anaconda3/lib/python3.9/site-packages/torch/nn/parallel/parallel_apply.py", line 61, in _worker
    output = module(*input, **kwargs)
  File "/home/siddsuresh97/packages/anaconda3/lib/python3.9/site-packages/torch/nn/modules/module.py", line 1102, in _call_impl
    return forward_call(*input, **kwargs)
  File "/home/siddsuresh97/Projects/cs839-autoencoder/models/resnet.py", line 38, in forward
    leuven_normspace = self.leuven_encoder(x)
  File "/home/siddsuresh97/packages/anaconda3/lib/python3.9/site-packages/torch/nn/modules/module.py", line 1102, in _call_impl
    return forward_call(*input, **kwargs)
  File "/home/siddsuresh97/Projects/cs839-autoencoder/models/resnet.py", line 97, in forward
    x = self.encoder(x)
  File "/home/siddsuresh97/Projects/cs839-autoencoder/models/resnet.py", line 97, in forward
    x = self.encoder(x)
  File "/home/siddsuresh97/packages/anaconda3/lib/python3.9/bdb.py", line 88, in trace_dispatch
    return self.dispatch_line(frame)
  File "/home/siddsuresh97/packages/anaconda3/lib/python3.9/bdb.py", line 112, in dispatch_line
    self.user_line(frame)
  File "/home/siddsuresh97/packages/anaconda3/lib/python3.9/pdb.py", line 262, in user_line
    self.interaction(frame, None)
  File "/home/siddsuresh97/.local/lib/python3.9/site-packages/IPython/core/debugger.py", line 336, in interaction
    OldPdb.interaction(self, frame, traceback)
  File "/home/siddsuresh97/packages/anaconda3/lib/python3.9/pdb.py", line 357, in interaction
    self._cmdloop()
  File "/home/siddsuresh97/packages/anaconda3/lib/python3.9/pdb.py", line 322, in _cmdloop
    self.cmdloop()
  File "/home/siddsuresh97/.local/lib/python3.9/site-packages/IPython/terminal/debugger.py", line 132, in cmdloop
    line = self.thread_executor.submit(
  File "/home/siddsuresh97/packages/anaconda3/lib/python3.9/concurrent/futures/_base.py", line 446, in result
    return self.__get_result()
  File "/home/siddsuresh97/packages/anaconda3/lib/python3.9/concurrent/futures/_base.py", line 391, in __get_result
    raise self._exception
  File "/home/siddsuresh97/packages/anaconda3/lib/python3.9/concurrent/futures/thread.py", line 58, in run
    result = self.fn(*self.args, **self.kwargs)
  File "/home/siddsuresh97/.local/lib/python3.9/site-packages/prompt_toolkit/shortcuts/prompt.py", line 1034, in prompt
    return self.app.run(
  File "/home/siddsuresh97/.local/lib/python3.9/site-packages/prompt_toolkit/application/application.py", line 978, in run
    return loop.run_until_complete(
  File "/home/siddsuresh97/packages/anaconda3/lib/python3.9/asyncio/base_events.py", line 647, in run_until_complete
    return future.result()
  File "/home/siddsuresh97/.local/lib/python3.9/site-packages/prompt_toolkit/application/application.py", line 891, in run_async
    await self.cancel_and_wait_for_background_tasks()
  File "/home/siddsuresh97/.local/lib/python3.9/site-packages/prompt_toolkit/application/application.py", line 1092, in cancel_and_wait_for_background_tasks
    await task
RuntimeError: Task <Task pending name='Task-8' coro=<Application.run_async() running at /home/siddsuresh97/.local/lib/python3.9/site-packages/prompt_toolkit/application/application.py:891> cb=[_run_until_complete_cb() at /home/siddsuresh97/packages/anaconda3/lib/python3.9/asyncio/base_events.py:184]> got Future <Task pending name='Task-62' coro=<KeyProcessor._start_timeout.<locals>.wait() running at /home/siddsuresh97/.local/lib/python3.9/site-packages/prompt_toolkit/key_binding/key_processor.py:397> wait_for=<Future cancelled>> attached to a different loop
If you suspect this is an IPython 8.5.0 bug, please report it at:
    https://github.com/ipython/ipython/issues
or send an email to the mailing list at ipython-dev@python.org
You can print a more detailed traceback right now with "%tb", or use "%debug"
to interactively debug it.
Extra-detailed tracebacks for bug-reporting purposes can be enabled via:
    %config Application.verbose_crash=True
Error in atexit._run_exitfuncs:
sqlite3.ProgrammingError: SQLite objects created in a thread can only be used in that same thread. The object was created in thread id 139769308771904 and this is thread id 139775746869056.
During handling of the above exception, another exception occurred:
Traceback (most recent call last):
  File "/home/siddsuresh97/.local/lib/python3.9/site-packages/IPython/core/history.py", line 831, in writeout_cache
    self._writeout_input_cache(conn)
  File "/home/siddsuresh97/.local/lib/python3.9/site-packages/IPython/core/history.py", line 814, in _writeout_input_cache
    conn.execute("INSERT INTO history VALUES (?, ?, ?, ?)",
sqlite3.ProgrammingError: SQLite objects created in a thread can only be used in that same thread. The object was created in thread id 139769308771904 and this is thread id 139775746869056.
Error in atexit._run_exitfuncs:
sqlite3.ProgrammingError: SQLite objects created in a thread can only be used in that same thread. The object was created in thread id 139769300379200 and this is thread id 139775746869056.
During handling of the above exception, another exception occurred:
Traceback (most recent call last):
  File "/home/siddsuresh97/.local/lib/python3.9/site-packages/IPython/core/history.py", line 831, in writeout_cache
    self._writeout_input_cache(conn)
  File "/home/siddsuresh97/.local/lib/python3.9/site-packages/IPython/core/history.py", line 814, in _writeout_input_cache
    conn.execute("INSERT INTO history VALUES (?, ?, ?, ?)",
sqlite3.ProgrammingError: SQLite objects created in a thread can only be used in that same thread. The object was created in thread id 139769300379200 and this is thread id 139775746869056.